Workbook

Sheet Home

Sheet INPUT DATA
A1: Input Data Sheet for Electronic-Class Record (ECR) for Class Adviser
B7: SCHOOL INFORMATION | J7: LEARNERS' DATA
C10: REGION | E10: : | F10: Region IV-A | K10: MALE | M10: LRN | N10: BIRTHDATE | P10: FEMALE | R10: LRN | S10: BIRTHDATE
C11: DIVISION | E11: : | F11: BATANGAS PROVINCE | K11: 1 | L11: Alcaraz, Joshmond Cuntapay | M11: 107743150040 | N11: 40159 | P11: 1 | Q11: Agustin, Maria Isabelle Maballo | R11: 107743150029 | S11: 08/28/2010
C12: CITY/MUNICIPALITY | E12: : | F12: TALISAY | K12: 2 | L12: Cabrera, Carl James Almendras | M12: 107741150061 | N12: 08/19/2010 | P12: 2 | Q12: Barba, Jewel Caraan | R12: 107743150121 | S12: 1/31/2010
C13: DISTRICT | E13: : | K13: 3 | L13: Cacal, Sydney Padilla | M13: 107736150048 | N13: 2/25/2010 | P13: 3 | Q13: Bartolome, Anne Joyce Alido | R13: 107738150047 | S13: 4/29/2010
K14: 4 | L14: Caringal, Raver | M14: 107739150008 | N14: 08/17/2010 | P14: 4 | Q14: Batallon, Lea Joy Aropon | R14: 109667150251 | S14: 40186
C15: SCHOOL ID | E15: : | F15: 342218 | K15: 5 | L15: De Grano, Andrey Jose Cabrera | M15: 402271150022 | N15: 11/24/2008 | P15: 5 | Q15: Blanco, Nica Ella Tolentino | R15: 107741150021 | S15: 40427
C16: SCHOOL NAME | E16: : | F16: TALISAY SENIOR HIGH SCHOOL | K16: 6 | L16: De Leon, Jherico Enriquez | M16: 107740150010 | N16: 12/22/2009 | P16: 6 | Q16: Cumabig, Trishia Nicole Blanco | R16: 107736140052 | S16: 11/30/2009
K17: 7 | L17: Dumalag, Matthew Oliver Caraan | M17: 107743150044 | N17: 40244 | P17: 7 | Q17: Diomampo, Judy Lyn De Chavez | R17: 107746150066 | S17: 11/21/2009
C18: SCHOOL YEAR | E18: : | F18: 2026-2027 | K18: 8 | L18: Hernandez, Nathan Jericho Santos | M18: 107736150060 | N18: 40299 | P18: 8 | Q18: Diones, Alexi Faye Dela Cruz | R18: 107738150034 | S18: 40269
C19: SCHOOL HEAD | E19: : | F19: JAENA N. DELA CERNA | K19: 9 | L19: Jumarang, Zaijan Charles Diola | M19: 107737150036 | N19: 03/14/2010 | P19: 9 | Q19: Galea, Jamica Rasco | R19: 433010150061 | S19: 8/30/2010
K20: 10 | L20: Mendoza, Ken Cyrus Villanueva | M20: 107742150006 | N20: 02/17/2010 | P20: 10 | Q20: Guevarra, Carlyn Avendaño | R20: 107737150049 | S20: 40491
K21: 11 | L21: Micua, Gerald De Leon | M21: 107740150027 | N21: 40334 | P21: 11 | Q21: Hilario, Patricia Gail Galisanao | R21: 163506140021 | S21: 39974
K22: 12 | L22: Pascua, Reinald Morta | M22: 163506150011 | N22: 40238 | P22: 12 | Q22: Jamila, Newrey Miaca Almendras | R22: 107743150033 | S22: 11/28/2009
B23: TEACHER, GRADE LEVEL, SECTION INFORMATION | K23: 13 | L23: Seña, John Joseph Nayangga | M23: 136605150121 | N23: 40519 | P23: 13 | Q23: Lacatan, Heart Anne Zamudio | R23: 107739150022 | S23: 2/14/2010
K24: 14 | L24: Velasco, Jake Nixon Lanzanas | M24: 100380150020 | N24: 40303 | P24: 14 | Q24: Laluna, Francess Brianna Balazon | R24: 107743150034 | S24: 40428
K25: 15 | P25: 15 | Q25: Licmo, Sheeona Pecate | R25: 107739150054 | S25: 5/15/2010
C26: ADVISER | E26: : | F26: NIÑO M. LUNA | K26: 16 | P26: 16 | Q26: Malabanan, Althea Viel | R26: 426030150021 | S26: 11/19/2009
C27: GRADE LEVEL | E27: : | F27: 11 | G27: (Accepts Grade 11 only) | K27: 17 | P27: 17 | Q27: Malabanan, Donalyn Monleon | R27: 107741150034 | S27: 40424
C28: TRACK | E28: : | F28: Academic | K28: 18 | P28: 18 | Q28: Malabanan, Femme Zyrene Pablo | R28: 107741140042 | S28: 11/24/2009
C29: SECTION | E29: : | F29: MEDICAL SCIENCE | K29: 19 | P29: 19 | Q29: Marca, Leyra Ann Almacha | R29: 112123150031 | S29: 8/23/2010
K30: 20 | P30: 20 | Q30: Maurillo, Althea Monica Canlobo | R30: 107740150034 | S30: 40097
C31: IMPORTANT NOTE: This is the official and final version of the file. All tabs are password-protected to prevent accidental formula edits and maintain the accuracy and integrity of the data. If you identify any inconsistencies or issues, particularly with the formulas, please report them for appropriate review and necessary correction. | K31: 21 | P31: 21 | Q31: Marasigan, Clarisse Mapili | R31: 107739150029 | S31: 40457
K32: 22 | P32: 22 | Q32: Mendoza, Dianne Solis | R32: 107736150116 | S32: 39976
K33: 23 | P33: 23 | Q33: Mission, Ruzhel Ann Llanos | R33: 107741150109 | S33: 05/13/2009
K34: 24 | P34: 24 | Q34: Opo, Krystal Mae Bacatan | R34: 107741150019 | S34: 7/29/2010
K35: 25 | P35: 25 | Q35: Orlanes, Janea Daphnie Cacao | R35: 107736150055 | S35: 39884
K36: 26 | P36: 26 | Q36: Salagantin, Jahanara Mendoza | R36: 107744160041 | S36: 10/13/2010
K37: 27 | P37: 27 | Q37: Sta. Isabel, Mary Antonette De Sagun | R37: 107739150046 | S37: 40339
B38: Sheet Protection Password: password123 | K38: 28 | P38: 28 | Q38: Suarez, Elijah Quirsten Miranda | R38: 107737150030 | S38: 40430
K39: 29 | P39: 29 | Q39: Suaybaguio, Mika Jean Blaza | R39: 423570150166 | S39: 10/31/2010
K40: 30 | P40: 30 | Q40: Villa, Danica Polinio | R40: 121534150001 | S40: 40246
K41: 31 | P41: 31
K42: 32 | P42: 32
K43: 33 | P43: 33
K44: 34 | P44: 34
K45: 35 | P45: 35
K46: 36 | P46: 36
K47: 37 | P47: 37
...

Sheet TERM 1 SUMMARY
A1: CLASS SUMMARY
D5: REGION | E5: =IF('INPUT DATA'!F10="","",'INPUT DATA'!F10) -> Region IV-A | I5: DIVISION | J5: =IF('INPUT DATA'!F11="","",'INPUT DATA'!F11) -> BATANGAS PROVINCE
D6: SCHOOL NAME | E6: =IF('INPUT DATA'!F16="","",'INPUT DATA'!F16) -> TALISAY SENIOR HIGH SCHOOL | I6: SCHOOL ID | J6: =IF('INPUT DATA'!F15="","",'INPUT DATA'!F15) -> 342218 | M6: SCHOOL YEAR | O6: =IF('INPUT DATA'!F18="","",'INPUT DATA'!F18) -> 2026-2027
B9: FIRST TERM | F9: GRADE LEVEL | G9: =IF('INPUT DATA'!F27="","",'INPUT DATA'!F27) -> 11 | L9: SECTION | O9: =IF('INPUT DATA'!F29="","",'INPUT DATA'!F29) -> MEDICAL SCIENCE
F10: TRACK | G10: =IF('INPUT DATA'!F28="","",'INPUT DATA'!F28) -> Academic | L10: ADVISER | O10: =IF('INPUT DATA'!F26="","",'INPUT DATA'!F26) -> NIÑO M. LUNA
B11: LEARNERS' NAMES | F11: LRN | H11: Date of Birth | I11: Age | J11: Sex | K11: Learning Areas
K12: Core Subjects | R12: Elective Subjects
K13: Effective Communication and Mabisang Komunikasyon | N13: General Mathematics | O13: General Science | P13: Life and Career Skills | Q13: PKLP | R13: Academic Elective 1
K14: Term Grade | L14: Effective Communication | M14: Mabisang Komunikasyon | R14: Biology 1
B15: MALE
B16: 1 | C16: =IF('INPUT DATA'!L11="","",'INPUT DATA'!L11) -> Alcaraz, Joshmond Cuntapay | F16: =IF('INPUT DATA'!M11="","",'INPUT DATA'!M11) -> 107743150040 | H16: =IF('INPUT DATA'!N11="","",'INPUT DATA'!N11) -> 40159 | I16: =IF(H16="","",DATEDIF(H16,TODAY(),"Y")) -> 16 | J16: M | K16: =IF(COUNT(L16:R16)=0,"",ROUND((L16+M16+N16+O16+P16+Q16+R16)/7,0)) -> 90 | L16: 91 | M16: 89 | N16: 89 | O16: 91 | P16: 92 | Q16: 89 | R16: 89
B17: 2 | C17: =IF('INPUT DATA'!L12="","",'INPUT DATA'!L12) -> Cabrera, Carl James Almendras | F17: =IF('INPUT DATA'!M12="","",'INPUT DATA'!M12) -> 107741150061 | H17: =IF('INPUT DATA'!N12="","",'INPUT DATA'!N12) -> 08/19/2010 | I17: =IF(H17="","",DATEDIF(H17,TODAY(),"Y")) -> #VALUE! | J17: M | K17: =IF(COUNT(L17:R17)=0,"",ROUND((L17+M17+N17+O17+P17+Q17+R17)/7,0)) -> 94 | L17: 94 | M17: 93 | N17: 93 | O17: 95 | P17: 95 | Q17: 95 | R17: 94
B18: 3 | C18: =IF('INPUT DATA'!L13="","",'INPUT DATA'!L13) -> Cacal, Sydney Padilla | F18: =IF('INPUT DATA'!M13="","",'INPUT DATA'!M13) -> 107736150048 | H18: =IF('INPUT DATA'!N13="","",'INPUT DATA'!N13) -> 2/25/2010 | I18: 16 | J18: M | K18: =IF(COUNT(L18:R18)=0,"",ROUND((L18+M18+N18+O18+P18+Q18+R18)/7,0)) -> 90 | L18: 88 | M18: 89 | N18: 90 | O18: 90 | P18: 91 | Q18: 90 | R18: 89
B19: 4 | C19: =IF('INPUT DATA'!L14="","",'INPUT DATA'!L14) -> Caringal, Raver | F19: =IF('INPUT DATA'!M14="","",'INPUT DATA'!M14) -> 107739150008 | H19: =IF('INPUT DATA'!N14="","",'INPUT DATA'!N14) -> 08/17/2010 | I19: 16 | J19: M | K19: =IF(COUNT(L19:R19)=0,"",ROUND((L19+M19+N19+O19+P19+Q19+R19)/7,0)) -> 91 | L19: 89 | M19: 90 | N19: 91 | O19: 90 | P19: 92 | Q19: 94 | R19: 88
B20: 5 | C20: =IF('INPUT DATA'!L15="","",'INPUT DATA'!L15) -> De Grano, Andrey Jose Cabrera | F20: =IF('INPUT DATA'!M15="","",'INPUT DATA'!M15) -> 402271150022 | H20: =IF('INPUT DATA'!N15="","",'INPUT DATA'!N15) -> 11/24/2008 | I20: =IF(H20="","",DATEDIF(H20,TODAY(),"Y")) -> #VALUE! | J20: M | K20: =IF(COUNT(L20:R20)=0,"",ROUND((L20+M20+N20+O20+P20+Q20+R20)/7,0)) -> 71 | M20: 83 | N20: 81 | O20: 85 | P20: 80 | Q20: 86 | R20: 84
B21: 6 | C21: =IF('INPUT DATA'!L16="","",'INPUT DATA'!L16) -> De Leon, Jherico Enriquez | F21: =IF('INPUT DATA'!M16="","",'INPUT DATA'!M16) -> 107740150010 | H21: =IF('INPUT DATA'!N16="","",'INPUT DATA'!N16) -> 12/22/2009 | I21: 16 | J21: M | K21: =IF(COUNT(L21:R21)=0,"",ROUND((L21+M21+N21+O21+P21+Q21+R21)/7,0)) -> 91 | L21: 92 | M21: 92 | N21: 88 | O21: 90 | P21: 93 | Q21: 95 | R21: 87
B22: 7 | C22: =IF('INPUT DATA'!L17="","",'INPUT DATA'!L17) -> Dumalag, Matthew Oliver Caraan | F22: =IF('INPUT DATA'!M17="","",'INPUT DATA'!M17) -> 107743150044 | H22: =IF('INPUT DATA'!N17="","",'INPUT DATA'!N17) -> 40244 | I22: 16 | J22: M | K22: =IF(COUNT(L22:R22)=0,"",ROUND((L22+M22+N22+O22+P22+Q22+R22)/7,0)) -> 92 | L22: 93 | M22: 90 | N22: 96 | O22: 94 | P22: 92 | Q22: 90 | R22: 91
B23: 8 | C23: =IF('INPUT DATA'!L18="","",'INPUT DATA'!L18) -> Hernandez, Nathan Jericho Santos | F23: =IF('INPUT DATA'!M18="","",'INPUT DATA'!M18) -> 107736150060 | H23: =IF('INPUT DATA'!N18="","",'INPUT DATA'!N18) -> 40299 | I23: =IF(H23="","",DATEDIF(H23,TODAY(),"Y")) -> 16 | J23: M | K23: =IF(COUNT(L23:R23)=0,"",ROUND((L23+M23+N23+O23+P23+Q23+R23)/7,0)) -> 83 | L23: 87 | M23: 82 | N23: 82 | O23: 80 | P23: 87 | Q23: 84 | R23: 80
B24: 9 | C24: =IF('INPUT DATA'!L19="","",'INPUT DATA'!L19) -> Jumarang, Zaijan Charles Diola | F24: =IF('INPUT DATA'!M19="","",'INPUT DATA'!M19) -> 107737150036 | H24: =IF('INPUT DATA'!N19="","",'INPUT DATA'!N19) -> 03/14/2010 | I24: 16 | J24: M | K24: =IF(COUNT(L24:R24)=0,"",ROUND((L24+M24+N24+O24+P24+Q24+R24)/7,0)) -> 87 | L24: 87 | M24: 90 | N24: 85 | O24: 87 | P24: 88 | Q24: 85 | R24: 84
B25: 10 | C25: =IF('INPUT DATA'!L20="","",'INPUT DATA'!L20) -> Mendoza, Ken Cyrus Villanueva | F25: =IF('INPUT DATA'!M20="","",'INPUT DATA'!M20) -> 107742150006 | H25: =IF('INPUT DATA'!N20="","",'INPUT DATA'!N20) -> 02/17/2010 | I25: 16 | J25: M | K25: =IF(COUNT(L25:R25)=0,"",ROUND((L25+M25+N25+O25+P25+Q25+R25)/7,0)) -> 86 | L25: 87 | M25: 88 | N25: 83 | O25: 84 | P25: 93 | Q25: 85 | R25: 85
B26: 11 | C26: =IF('INPUT DATA'!L21="","",'INPUT DATA'!L21) -> Micua, Gerald De Leon | F26: =IF('INPUT DATA'!M21="","",'INPUT DATA'!M21) -> 107740150027 | H26: =IF('INPUT DATA'!N21="","",'INPUT DATA'!N21) -> 40334 | I26: =IF(H26="","",DATEDIF(H26,TODAY(),"Y")) -> 16 | J26: M | K26: =IF(COUNT(L26:R26)=0,"",ROUND((L26+M26+N26+O26+P26+Q26+R26)/7,0)) -> 86 | L26: 86 | M26: 86 | N26: 81 | O26: 90 | P26: 90 | Q26: 87 | R26: 84
B27: 12 | C27: =IF('INPUT DATA'!L22="","",'INPUT DATA'!L22) -> Pascua, Reinald Morta | F27: =IF('INPUT DATA'!M22="","",'INPUT DATA'!M22) -> 163506150011 | H27: =IF('INPUT DATA'!N22="","",'INPUT DATA'!N22) -> 40238 | I27: =IF(H27="","",DATEDIF(H27,TODAY(),"Y")) -> 16 | J27: M | K27: =IF(COUNT(L27:R27)=0,"",ROUND((L27+M27+N27+O27+P27+Q27+R27)/7,0)) -> 88 | L27: 87 | M27: 89 | N27: 86 | O27: 88 | P27: 91 | Q27: 89 | R27: 85
B28: 13 | C28: =IF('INPUT DATA'!L23="","",'INPUT DATA'!L23) -> Seña, John Joseph Nayangga | F28: =IF('INPUT DATA'!M23="","",'INPUT DATA'!M23) -> 136605150121 | H28: =IF('INPUT DATA'!N23="","",'INPUT DATA'!N23) -> 40519 | I28: =IF(H28="","",DATEDIF(H28,TODAY(),"Y")) -> 15 | J28: M | K28: =IF(COUNT(L28:R28)=0,"",ROUND((L28+M28+N28+O28+P28+Q28+R28)/7,0)) -> 91 | L28: 91 | M28: 90 | N28: 95 | O28: 92 | P28: 95 | Q28: 86 | R28: 89
B29: 14 | C29: =IF('INPUT DATA'!L24="","",'INPUT DATA'!L24) -> Velasco, Jake Nixon Lanzanas | F29: =IF('INPUT DATA'!M24="","",'INPUT DATA'!M24) -> 100380150020 | H29: =IF('INPUT DATA'!N24="","",'INPUT DATA'!N24) -> 40303 | I29: =IF(H29="","",DATEDIF(H29,TODAY(),"Y")) -> 16 | J29: M | K29: =IF(COUNT(L29:R29)=0,"",ROUND((L29+M29+N29+O29+P29+Q29+R29)/7,0)) -> 88 | L29: 88 | M29: 88 | N29: 86 | O29: 87 | P29: 90 | Q29: 90 | R29: 84
B30: 15 | C30: =IF('INPUT DATA'!L25="","",'INPUT DATA'!L25) | F30: =IF('INPUT DATA'!M25="","",'INPUT DATA'!M25) | H30: =IF('INPUT DATA'!N25="","",'INPUT DATA'!N25) | I30: 16 | J30: M | K30: =IF(COUNT(L30:R30)=0,"",ROUND((L30+M30+N30+O30+P30+Q30+R30)/7,0))
B31: 16 | C31: =IF('INPUT DATA'!L26="","",'INPUT DATA'!L26) | F31: =IF('INPUT DATA'!M26="","",'INPUT DATA'!M26) | H31: =IF('INPUT DATA'!N26="","",'INPUT DATA'!N26) | I31: =IF(H31="","",DATEDIF(H31,TODAY(),"Y")) | J31: M | K31: =IF(COUNT(L31:R31)=0,"",ROUND((L31+M31+N31+O31+P31+Q31+R31)/7,0))
B32: 17 | C32: =IF('INPUT DATA'!L27="","",'INPUT DATA'!L27) | F32: =IF('INPUT DATA'!M27="","",'INPUT DATA'!M27) | H32: =IF('INPUT DATA'!N27="","",'INPUT DATA'!N27) | I32: =IF(H32="","",DATEDIF(H32,TODAY(),"Y")) | J32: M | K32: =IF(COUNT(L32:R32)=0,"",ROUND((L32+M32+N32+O32+P32+Q32+R32)/7,0))
B33: 18 | C33: =IF('INPUT DATA'!L28="","",'INPUT DATA'!L28) | F33: =IF('INPUT DATA'!M28="","",'INPUT DATA'!M28) | H33: =IF('INPUT DATA'!N28="","",'INPUT DATA'!N28) | I33: =IF(H33="","",DATEDIF(H33,TODAY(),"Y")) | J33: M | K33: =IF(COUNT(L33:R33)=0,"",ROUND((L33+M33+N33+O33+P33+Q33+R33)/7,0))
B34: 19 | C34: =IF('INPUT DATA'!L29="","",'INPUT DATA'!L29) | F34: =IF('INPUT DATA'!M29="","",'INPUT DATA'!M29) | H34: =IF('INPUT DATA'!N29="","",'INPUT DATA'!N29) | I34: =IF(H34="","",DATEDIF(H34,TODAY(),"Y")) | J34: M | K34: =IF(COUNT(L34:R34)=0,"",ROUND((L34+M34+N34+O34+P34+Q34+R34)/7,0))
B35: 20 | C35: =IF('INPUT DATA'!L30="","",'INPUT DATA'!L30) | F35: =IF('INPUT DATA'!M30="","",'INPUT DATA'!M30) | H35: =IF('INPUT DATA'!N30="","",'INPUT DATA'!N30) | I35: =IF(H35="","",DATEDIF(H35,TODAY(),"Y")) | J35: M | K35: =IF(COUNT(L35:R35)=0,"",ROUND((L35+M35+N35+O35+P35+Q35+R35)/7,0))
B36: 21 | C36: =IF('INPUT DATA'!L31="","",'INPUT DATA'!L31) | F36: =IF('INPUT DATA'!M31="","",'INPUT DATA'!M31) | H36: =IF('INPUT DATA'!N31="","",'INPUT DATA'!N31) | I36: =IF(H36="","",DATEDIF(H36,TODAY(),"Y")) | J36: M | K36: =IF(COUNT(L36:R36)=0,"",ROUND((L36+M36+N36+O36+P36+Q36+R36)/7,0))
B37: 22 | C37: =IF('INPUT DATA'!L32="","",'INPUT DATA'!L32) | F37: =IF('INPUT DATA'!M32="","",'INPUT DATA'!M32) | H37: =IF('INPUT DATA'!N32="","",'INPUT DATA'!N32) | I37: =IF(H37="","",DATEDIF(H37,TODAY(),"Y")) | J37: M | K37: =IF(COUNT(L37:R37)=0,"",ROUND((L37+M37+N37+O37+P37+Q37+R37)/7,0))
B38: 23 | C38: =IF('INPUT DATA'!L33="","",'INPUT DATA'!L33) | F38: =IF('INPUT DATA'!M33="","",'INPUT DATA'!M33) | H38: =IF('INPUT DATA'!N33="","",'INPUT DATA'!N33) | I38: =IF(H38="","",DATEDIF(H38,TODAY(),"Y")) | J38: M | K38: =IF(COUNT(L38:R38)=0,"",ROUND((L38+M38+N38+O38+P38+Q38+R38)/7,0))
B39: 24 | C39: =IF('INPUT DATA'!L34="","",'INPUT DATA'!L34) | F39: =IF('INPUT DATA'!M34="","",'INPUT DATA'!M34) | H39: =IF('INPUT DATA'!N34="","",'INPUT DATA'!N34) | J39: M | K39: =IF(COUNT(L39:R39)=0,"",ROUND((L39+M39+N39+O39+P39+Q39+R39)/7,0))
B40: 25 | C40: =IF('INPUT DATA'!L35="","",'INPUT DATA'!L35) | F40: =IF('INPUT DATA'!M35="","",'INPUT DATA'!M35) | H40: =IF('INPUT DATA'!N35="","",'INPUT DATA'!N35) | I40: =IF(H40="","",DATEDIF(H40,TODAY(),"Y"))
B41: 26 | C41: =IF('INPUT DATA'!L36="","",'INPUT DATA'!L36) | F41: =IF('INPUT DATA'!M36="","",'INPUT DATA'!M36) | H41: =IF('INPUT DATA'!N36="","",'INPUT DATA'!N36) | I41: =IF(H41="","",DATEDIF(H41,TODAY(),"Y"))
B42: 27 | C42: =IF('INPUT DATA'!L37="","",'INPUT DATA'!L37) | F42: =IF('INPUT DATA'!M37="","",'INPUT DATA'!M37) | H42: =IF('INPUT DATA'!N37="","",'INPUT DATA'!N37) | I42: =IF(H42="","",DATEDIF(H42,TODAY(),"Y"))
B43: 28 | C43: =IF('INPUT DATA'!L38="","",'INPUT DATA'!L38) | F43: =IF('INPUT DATA'!M38="","",'INPUT DATA'!M38) | H43: =IF('INPUT DATA'!N38="","",'INPUT DATA'!N38) | I43: =IF(H43="","",DATEDIF(H43,TODAY(),"Y"))
B44: 29 | C44: =IF('INPUT DATA'!L39="","",'INPUT DATA'!L39) | F44: =IF('INPUT DATA'!M39="","",'INPUT DATA'!M39) | H44: =IF('INPUT DATA'!N39="","",'INPUT DATA'!N39) | I44: =IF(H44="","",DATEDIF(H44,TODAY(),"Y"))
B45: 30 | C45: =IF('INPUT DATA'!L40="","",'INPUT DATA'!L40) | F45: =IF('INPUT DATA'!M40="","",'INPUT DATA'!M40) | H45: =IF('INPUT DATA'!N40="","",'INPUT DATA'!N40) | I45: =IF(H45="","",DATEDIF(H45,TODAY(),"Y"))
...

Sheet Card_SF9
AK3: Needs more practice to improve understanding.
B4: Republic of the Philippines | Q4: Month | R4: Jun | S4: Jul | T4: Aug | U4: Sep | V4: Oct | W4: Nov | X4: Dec | Y4: Jan | Z4: Feb | AA4: Mar | AB4: Apr | AC4: Total | AK4: Needs to work harder on difficult lessons.
Q5: No. of Class Days | R5: =#REF! -> #REF! | S5: =#REF! -> #REF! | T5: =#REF! -> #REF! | U5: =#REF! -> #REF! | V5: =#REF! -> #REF! | W5: =#REF! -> #REF! | X5: =#REF! -> #REF! | Y5: =#REF! -> #REF! | ... AB5: =#REF! -> #REF! | AC5: =SUM(R5:AB6) -> #REF! | AK5: Shows effort but needs more guidance.
AK6: Can improve with more focus and effort.
B7: REGION IV - A (CALABARZON) | Q7: No. of Days Present | R7: =IF(#REF!="","",IFERROR(VLOOKUP(C17,#REF!,4,0),"")) -> #REF! | S7: =IF(#REF!="","",IFERROR(VLOOKUP(C17,#REF!,5,0),"")) -> #REF! | T7: =IF(#REF!="","",IFERROR(VLOOKUP(C17,#REF!,6,0),"")) -> #REF! | U7: =IF(#REF!="","",IFERROR(VLOOKUP(C17,#REF!,7,0),"")) -> #REF! | V7: =IF(#REF!="","",IFERROR(VLOOKUP(C17,#REF!,8,0),"")) -> #REF! | W7: =IF(#REF!="","",IFERROR(VLOOKUP(C17,#REF!,9,0),"")) -> #REF! | X7: =IF(#REF!="","",IFERROR(VLOOKUP(C17,#REF!,10,0),"")) -> #REF! | Y7: =IF(#REF!="","",IFERROR(VLOOKUP(C17,#REF!,11,0),"")) -> #REF! | Z7: =IF(#REF!="","",IFERROR(VLOOKUP(C17,#REF!,12,0),"")) -> #REF! | AA7: =IF(#REF!="","",IFERROR(VLOOKUP(C17,#REF!,13,0),"")) -> #REF! | AB7: =IF(#REF!="","",IFERROR(VLOOKUP(C17,#REF!,14,0),"")) -> #REF! | AC7: =SUM(R7:AB8) -> #REF! | AK7: Needs to participate more in class.
B8: SCHOOLS DIVISION OF BATANGAS PROVINCE | AK8: Shows potential but needs more practice.
B9: TALISAY DISTRICT | Q9: No. of Days Absent | R9: =IF(R7="","",ABS(R5-R7)) -> #REF! | S9: =IF(S7="","",ABS(S5-S7)) -> #REF! | T9: =IF(T7="","",ABS(T5-T7)) -> #REF! | U9: =IF(U7="","",ABS(U5-U7)) -> #REF! | V9: =IF(V7="","",ABS(V5-V7)) -> #REF! | W9: =IF(W7="","",ABS(W5-W7)) -> #REF! | X9: =IF(X7="","",ABS(X5-X7)) -> #REF! | Y9: =IF(Y7="","",ABS(Y5-Y7)) -> #REF! | ... AB9: =IF(AB7="","",ABS(AB5-AB7)) -> #REF! | AC9: =ABS(AC5-AC7) -> #REF! | AK9: Needs to improve study habits.
B10: TALISAY, BATANGAS | AK10: Needs closer attention during discussions.
AK11: Shows improvement but still needs practice.
B12: TALISAY SENIOR HIGH SCHOOL | AK12: Needs to stay focused during activities.
AK13: Should complete tasks on time.
B14: LEARNER'S PERFORMANCE REPORT | Q14: TEACHER'S COMMENTS / REMARKS | AK14: Needs to develop better study habits.
B15: School Year 2026-2027 | Q15: Term 1 | R15: Needs more practice to improve understanding. | AK15: Shows satisfactory progress in class.
AK16: Continues to improve in different areas.
B17: Name: | C17: Salagantin, Jahanara Mendoza | H17: Age: | I17: 15 | J17: Sex: | K17: =IF(C17="","",VLOOKUP(C17,'TERM 1 SUMMARY'!C16:R116,8,0)) -> F | AK17: Performs well with regular guidance.
B18: LRN: | C18: 107744160041 | H18: Grade: | I18: =IF('INPUT DATA'!F27="","",'INPUT DATA'!F27) -> 11 | J18: Section: | K18: =IF('INPUT DATA'!F29="","",'INPUT DATA'!F29) -> MEDICAL SCIENCE | AK18: Shows good effort in completing tasks.
B19: Track (SHS only): | E19: =IF('INPUT DATA'!F28="","",'INPUT DATA'!F28) -> Academic | Q19: Term 2 | AK19: Participates in class activities.
AK20: Understands most of the lessons.
B21: Dear Parents, | AK21: Shows steady progress this term.
C22: This Performance Report presents your child's progress and achievement | AK22: Does well when given proper guidance.
B23: in the different learning areas. | Q23: Term 3 | AK23: Completes most tasks on time.
C24: The school welcomes you to reach out should you wish to know more about your | AK24: Shows willingness to learn.
B25: child's learning and performance. | AK25: Has shown good improvement.
AK26: Participates well during discussions.
B27: =IF('INPUT DATA'!F19="","",'INPUT DATA'!F19) -> JAENA N. DELA CERNA | H27: =IF('INPUT DATA'!F26="","",'INPUT DATA'!F26) -> NIÑO M. LUNA | AK27: Can improve further with more effort.
B28: School Head | H28: Adviser | Q28: PARENT/S GUARDIAN'S SIGNATURE | AK28: Shows a positive attitude toward learning.
B29: LEARNING PROGRESS AND ACHIEVEMENT | R29: Term 1 | AK29: Works well during classroom activities.
B30: Learning Areas | F30: TERM | I30: Units | J30: Final Grade | K30: Remarks | R30: Term 2 | AK30: Continues to develop good study habits.
F31: T1 | G31: T2 | H31: T3 | R31: Term 3 | AK31: Performs better when focused.
B32: Core Subjects | AK32: Shows consistent effort in class.
B33: Effective Communication /Mabisang Komunikasyon | G33: =IF(#REF!="","",VLOOKUP(C17,#REF!,11,0)) -> #REF! | H33: =IF(#REF!="","",VLOOKUP(C17,#REF!,11,0)) -> #REF! | K33: =IF(J33="","",IF(J33>=75,"Passed","Failed")) | L33: =J33*I33 -> 0 | Q33: CERTIFICATE OF TRANSFER | AK33: Completes assigned activities responsibly.
B34: Effective Communication | F34: =IF('TERM 1 SUMMARY'!K16="","",VLOOKUP(C17,'TERM 1 SUMMARY'!C16:R116,10,0)) -> 88 | G34: =IF(#REF!="","",VLOOKUP(C17,#REF!,11,0)) -> #REF! | H34: =IF(#REF!="","",VLOOKUP(C17,#REF!,11,0)) -> #REF! | Q34: This is to certify that the above-named learner has satisfactorily completed the requirements | AK34: Can achieve more with continued effort.
B35: Mabisang Komunikasyon | F35: =IF('TERM 1 SUMMARY'!K16="","",VLOOKUP(C17,'TERM 1 SUMMARY'!C16:R116,11,0)) -> 91 | G35: =IF(#REF!="","",VLOOKUP(C17,#REF!,10,0)) -> #REF! | H35: =IF(#REF!="","",VLOOKUP(C17,#REF!,10,0)) -> #REF! | Q35: for the grade level indicated. | AE35: =IF(COUNT(F31:H31)=0,"",ROUND((F31+G31+H31)/3,0)) | AK35: Shows excellent understanding of the lessons.
B36: General Mathematics | F36: =IF('TERM 1 SUMMARY'!K16="","",VLOOKUP(C17,'TERM 1 SUMMARY'!C16:R116,12,0)) -> 81 | G36: =IF(#REF!="","",VLOOKUP(C17,#REF!,12,0)) -> #REF! | H36: =IF(#REF!="","",VLOOKUP(C17,#REF!,12,0)) -> #REF! | K36: =IF(J36="","",IF(J36>=75,"Passed","Failed")) | L36: =J36*I36 -> 0 | AK36: Consistently performs well in class.
B37: General Science | F37: =IF('TERM 1 SUMMARY'!K16="","",VLOOKUP(C17,'TERM 1 SUMMARY'!C16:R116,13,0)) -> 84 | G37: =IF(#REF!="","",VLOOKUP(C17,#REF!,13,0)) -> #REF! | H37: =IF(#REF!="","",VLOOKUP(C17,#REF!,13,0)) -> #REF! | K37: =IF(J37="","",IF(J37>=75,"Passed","Failed")) | L37: =J37*I37 -> 0 | Q37: Admitted to Grade: | AK37: Shows strong interest in learning.
B38: Life and Career Skills | F38: =IF('TERM 1 SUMMARY'!K16="","",VLOOKUP(C17,'TERM 1 SUMMARY'!C16:R116,14,0)) -> 89 | G38: =IF(#REF!="","",VLOOKUP(C17,#REF!,14,0)) -> #REF! | H38: =IF(#REF!="","",VLOOKUP(C17,#REF!,14,0)) -> #REF! | K38: =IF(J38="","",IF(J38>=75,"Passed","Failed")) | L38: =J38*I38 -> 0 | Q38: Eligible for Admission to Grade: | AK38: Completes tasks with confidence.
B39: Pag-Aaral ng Kasaysayan at Lipunang Pilipino | F39: =IF('TERM 1 SUMMARY'!K16="","",VLOOKUP(C17,'TERM 1 SUMMARY'!C16:R116,15,0)) -> 88 | G39: =IF(#REF!="","",VLOOKUP(C17,#REF!,15,0)) -> #REF! | H39: =IF(#REF!="","",VLOOKUP(C17,#REF!,15,0)) -> #REF! | K39: =IF(J39="","",IF(J39>=75,"Passed","Failed")) | L39: =J39*I39 -> 0 | X39: =IF('INPUT DATA'!F26="","",'INPUT DATA'!F26) -> NIÑO M. LUNA | AK39: Actively participates in discussions.
B40: Elective Subjects | Q40: Approved: | X40: Adviser | AK40: Demonstrates excellent study habits.
B41: Biology 1 | F41: =IF('TERM 1 SUMMARY'!K16="","",VLOOKUP(C17,'TERM 1 SUMMARY'!C16:R116,16,0)) -> 86 | K41: =IF(J41="","",IF(J41>=75,"Passed","Failed")) | L41: =J41*I41 -> 0 | Q41: =IF('INPUT DATA'!F19="","",'INPUT DATA'!F19) -> JAENA N. DELA CERNA | AK41: Shows initiative in classroom activities.
G42: =IF(#REF!="","",VLOOKUP(C17,#REF!,16,0)) -> #REF! | J42: =IF(SUM(F42:H42)=0,"",ROUND((F42+H42+G42)*I42/I42,0)) -> #REF! | K42: =IF(J42="","",IF(J42>=75,"Passed","Failed")) -> #REF! | L42: =J42*I42 -> #REF! | AK42: Shows excellent progress this term.
...
